<?xml version="1.0" encoding="utf-8"?>
<!-- This URDF was automatically created by SolidWorks to URDF Exporter! Originally created by Stephen Brawner (brawner@gmail.com) 
     Commit Version: 1.5.1-0-g916b5db  Build Version: 1.5.7152.31018
     For more information, please see http://wiki.ros.org/sw_urdf_exporter -->
<robot
  name="bada_g2_description">
  <link
    name="base_footprint_link">
  </link>
  <link
    name="base_link">
    <inertial>
      <origin
        xyz="0 0 0.137811398780425"
        rpy="0 0 0" />
      <mass
        value="7.21845660038506" />
      <inertia
        ixx="0.0406882353905042"
        ixy="1.07764868445934E-06"
        ixz="0.00163731386802838"
        iyy="0.0420116717478872"
        iyz="1.3334920258216E-06"
        izz="0.0765562030870485" />
    </inertial>
    <visual>
      <origin
        xyz="0 0 0"
        rpy="0 0 0" />
      <geometry>
        <mesh
          filename="package://bada_g2_description/meshes/base_link.STL" />
      </geometry>
      <material
        name="">
        <color
          rgba="0.792156862745098 0.819607843137255 0.933333333333333 1" />
      </material>
    </visual>
    <collision>
      <origin
        xyz="0 0 0"
        rpy="0 0 0" />
      <geometry>
        <mesh
          filename="package://bada_g2_description/meshes/base_link.STL" />
      </geometry>
    </collision>
    <collision name="caster_front_collision">
      <origin rpy=" 0 0 0" xyz="-0.13 0 -0.0052"/>
      <geometry>
      <sphere radius="0.007"/>
      </geometry>
      <surface>
      <friction>
        <ode>
        <mu>0</mu>
        <mu2>0</mu2>
        <slip1>1.0</slip1>
        <slip2>1.0</slip2>
        </ode>
      </friction>
      </surface>
    </collision>
    <visual name="caster_front_visual">
      <origin rpy=" 0 0 0" xyz="-0.13 0 -0.0052"/>
      <geometry>
      <sphere radius="0.007"/>
      </geometry>
    </visual>
  </link>
  <joint
    name="base_link_joint"
    type="fixed">
    <origin
      xyz="0 0 -0.075"
      rpy="0 0 0" />
    <parent
      link="base_footprint_link" />
    <child
      link="base_link" />
    <axis
      xyz="0 0 0" />
  </joint>
  <link
    name="L_link">
    <inertial>
      <origin
        xyz="2.77555756156289E-17 -0.0105 0"
        rpy="0 0 0" />
      <mass
        value="0.0812700200410188" />
      <inertia
        ixx="4.08495570817307E-05"
        ixy="-9.67407626570133E-20"
        ixz="-2.33937016987653E-21"
        iyy="7.66250906473836E-05"
        iyz="-2.5553360511772E-22"
        izz="4.08495570817308E-05" />
    </inertial>
    <visual>
      <origin
        xyz="0 0 0"
        rpy="0 0 0" />
      <geometry>
        <mesh
          filename="package://bada_g2_description/meshes/L_link.STL" />
      </geometry>
      <material
        name="">
        <color
          rgba="0.666666666666667 0.698039215686274 0.768627450980392 1" />
      </material>
    </visual>
    <collision>
      <origin
        xyz="0 0 0"
        rpy="0 0 0" />
      <geometry>
        <mesh
          filename="package://bada_g2_description/meshes/L_link.STL" />
      </geometry>
    </collision>
  </link>
  <joint
    name="L_joint"
    type="continuous">
    <origin
      xyz="0.0783012581840955 0.120003013664007 0.0330000000000001"
      rpy="0 0 0" />
    <parent
      link="base_link" />
    <child
      link="L_link" />
    <axis
      xyz="0 1 0" />
  </joint>
  <link
    name="R_link">
    <inertial>
      <origin
        xyz="-2.77555756156289E-17 0.0105 0"
        rpy="0 0 0" />
      <mass
        value="0.0812700200410188" />
      <inertia
        ixx="4.08495570817307E-05"
        ixy="-9.67407626570133E-20"
        ixz="-2.33937016987653E-21"
        iyy="7.66250906473836E-05"
        iyz="-2.5553360511772E-22"
        izz="4.08495570817308E-05" />
    </inertial>
    <visual>
      <origin
        xyz="0 0 0"
        rpy="0 0 0" />
      <geometry>
        <mesh
          filename="package://bada_g2_description/meshes/R_link.STL" />
      </geometry>
      <material
        name="">
        <color
          rgba="0.666666666666667 0.698039215686274 0.768627450980392 1" />
      </material>
    </visual>
    <collision>
      <origin
        xyz="0 0 0"
        rpy="0 0 0" />
      <geometry>
        <mesh
          filename="package://bada_g2_description/meshes/R_link.STL" />
      </geometry>
    </collision>
  </link>
  <joint
    name="R_joint"
    type="continuous">
    <origin
      xyz="0.0783012581840955 -0.120003013664007 0.0330000000000001"
      rpy="0 0 0" />
    <parent
      link="base_link" />
    <child
      link="R_link" />
    <axis
      xyz="0 1 0" />
  </joint>


  <!-- rplidar -->

  <joint name="rplidar_joint" type="fixed">
    <axis xyz="0 1 0" />
    <origin xyz="0.145 0 0.085" rpy="0 0 0"/> <!--rpy : 0 0 3.14-->
    <parent link="base_link"/>
    <child link="laser"/>
  </joint>


  <link name="laser">
    <collision>
      <origin xyz="0 0 -0.0308" rpy="1.5707 0 4.71"/>
      <geometry>
        <mesh filename="package://my_mobile/meshes/rplidar.dae" scale="0.001 0.001 0.001" />
      </geometry>
    </collision>

    <visual>
      <origin xyz="0 0 -0.0308" rpy="1.5707 0 4.71"/>
      <geometry>
        <mesh filename="package://my_mobile/meshes/rplidar.dae" scale="0.001 0.001 0.001" />
      </geometry>
    </visual>

    <inertial>
      <mass value="1e-5" />
      <origin xyz="0 0 -0.0308" rpy="1.5707 0 4.71"/>
      <inertia ixx="0" ixy="0" ixz="0" iyy="0" iyz="0" izz="0" />
    </inertial>
  </link>

<!-- plugin -->

  <gazebo>
    <plugin filename="libgazebo_ros_diff_drive.so" name="differential_drive_controller">
      <legacyMode>false</legacyMode>
      <alwaysOn>true</alwaysOn>
      <updateRate>20</updateRate>
      <leftJoint>L_joint</leftJoint>
      <rightJoint>R_joint</rightJoint>
      <wheelSeparation>0.22</wheelSeparation>
      <wheelDiameter>0.084</wheelDiameter>
      <torque>0.1</torque>
      <commandTopic>cmd_vel</commandTopic>
      <odometryTopic>odom</odometryTopic>
      <odometryFrame>odom</odometryFrame>
      <robotBaseFrame>base_link</robotBaseFrame>
      <rosDebugLevel>ns</rosDebugLevel>
      <publishWheelTF>false</publishWheelTF>
      <publishOdomTF>true</publishOdomTF>
      <publishWheelJointState>false</publishWheelJointState>
      <wheelAcceleration>0</wheelAcceleration>
      <wheelTorque>5</wheelTorque>
      <odometrySource>1</odometrySource>
      <publishTf>1</publishTf>
    </plugin>
  </gazebo>

<gazebo reference="laser">
    <sensor type="ray" name="head_rplidar_sensor">
      <pose>0 0 0.06 0 0 0</pose>
      <visualize>true</visualize>
      <update_rate>40</update_rate>
      <ray>
        <scan>
          <horizontal>
            <samples>720</samples>
            <resolution>1</resolution>
            <min_angle>1.57079632</min_angle>
            <max_angle>-1.57079632</max_angle>
          </horizontal>
        </scan>
        <range>
          <min>0.15</min>
          <max>6.0</max>
          <resolution>0.01</resolution>
        </range>
        <noise>
          <type>gaussian</type>
          <mean>0.0</mean>
          <stddev>0.01</stddev>
        </noise>
      </ray>
      <plugin name="gazebo_ros_head_rplidar_controller" filename="libgazebo_ros_laser.so">
        <topicName>scan</topicName>
        <frameName>laser</frameName>
      </plugin>
    </sensor>
  </gazebo> 

</robot>